<?xml version="1.0"?>
<robot name="arm_4dof">

  <!-- ================= BASE ================= -->
  <link name="base">
    <visual>
      <geometry>
        <mesh filename="4_dof_meshes/base.stl" scale="0.01 0.01 0.01"/>
      </geometry>
    </visual>

    <collision>
      <origin xyz="0.0 0.0 0.0" rpy="0 0 0"/>
      <geometry>
        <box size="2.0 2.0 0.05"/>
      </geometry>
    </collision>
  </link>

  <!-- Base → Shoulder (Yaw around Z) -->
  <joint name="joint1_base_yaw" type="revolute">
    <parent link="base"/>
    <child link="shoulder"/>
    <origin xyz="0 0 0.0" rpy="0 0 0"/>
    <axis xyz="0 0 1"/>
    <limit lower="-3.14" upper="3.14" effort="10" velocity="1"/>
  </joint>

   <!-- ================= SHOULDER ================= -->
  <link name="shoulder">
    <visual>
      <geometry>
        <mesh filename="4_dof_meshes/shoulder.stl" scale="0.01 0.01 0.01"/>
      </geometry>
    </visual>

    <collision>
      <origin xyz="0.128 0 0.25" rpy="0 0 0"/>
      <geometry>
        <box size="0.125 0.22 0.25"/>
      </geometry>
    </collision>
  </link>



  <!-- Shoulder → Arm (Pitch around X) -->
  <joint name="joint2_shoulder_pitch" type="revolute">
    <parent link="shoulder"/>
    <child link="arm"/>
    <origin xyz="0 0 0.35" rpy="0 0 0"/>
    <axis xyz="1 0 0"/>
    <limit lower="-1.57" upper="1.57" effort="10" velocity="1"/>
  </joint>

  <!-- ================= ARM ================= -->
  <link name="arm">
    <visual>
      <geometry>
        <mesh filename="4_dof_meshes/arm_trans.stl" scale="0.01 0.01 0.01"/>
      </geometry>
    </visual>

    <collision>
      <origin xyz="-0.128 0 0.65"/>
      <geometry>
        <box size="0.125 0.125 0.75"/>
      </geometry>
    </collision>

    <collision>
      <origin xyz="-0.125 0.36 1.225" rpy="0 0 0"/>
      <geometry>
        <box size="0.0 0.0 0.0"/>
      </geometry>
    </collision>
  </link>



  <!-- Arm → Forearm (Pitch around X) -->
  <joint name="joint3_elbow_pitch" type="revolute">
    <parent link="arm"/>
    <child link="forearm"/>
    <origin xyz="0 0.4 1.225" rpy="0 0 0"/>
    <axis xyz="1 0 0"/>
    <limit lower="-3.14" upper="3.14" effort="10" velocity="1"/>
  </joint>

  <!-- ================= FOREARM ================= -->
  <link name="forearm">
    <visual>
      <geometry>
        <mesh filename="4_dof_meshes/forearm_trans.stl" scale="0.01 0.01 0.01"/>
      </geometry>
    </visual>

    <collision>
      <origin xyz="0.128 0.0 -0.43" rpy="0 0 0"/>
      <geometry>
        <box size="0.1 0.15 0.58"/>
      </geometry>
    </collision>
  </link>



  <!-- Forearm → Wrist (Pitch around X) -->
  <joint name="joint4_wrist_pitch" type="revolute">
    <parent link="forearm"/>
    <child link="wrist"/>
    <origin xyz="0 0 -0.91" rpy="0 0 0"/>
    <axis xyz="1 0 0"/>
    <limit lower="-1.57" upper="1.57" effort="10" velocity="1"/>
  </joint>

  <!-- ================= WRIST ================= -->
  <link name="wrist">
    <visual>
      <geometry>
        <mesh filename="4_dof_meshes/wrist_trans.stl" scale="0.01 0.01 0.01"/>
      </geometry>
    </visual>

    <collision>
      <origin xyz="-0.15 0.0 0.29" rpy="0 0 0"/>
      <geometry>
        <box size="0.125 0.145 0.45"/>
      </geometry>
    </collision>
  </link>

  <!-- wrist → ee -->
  <joint name="wrist_ee" type="fixed">
    <parent link="wrist"/>
    <child link="end_effector"/>
    <origin xyz="0 -0.01 0.6" rpy="0 0 0"/>
    <axis xyz="1 0 0"/>
  </joint>

  <!-- ================= EE ================= -->
  <link name="end_effector">
    <visual>
      <geometry>
        <mesh filename="4_dof_meshes/end_effector_trans.stl" scale="0.01 0.01 0.01"/>
      </geometry>
    </visual>
  </link>




</robot>
